Workbook

Sheet Monday
A1: timestamp | B1: route_id | C1: start | D1: end | E1: distance_km | F1: duration_in_traffic_min | G1: speed_km/h
A2: 45810.292 | B2: 1 | C2: 41.32516738436008, 69.30379886174566 | D2: 41.327552032716724, 69.28609735456061 | E2: 1.53 | F2: 2.75 | G2: =E2*60/F2 -> 33.381818
A3: 45810.292 | B3: 2 | C3: 41.327552032716724, 69.28609735456061 | D3: 41.332180445326756, 69.26923046640113 | E3: 1.57 | F3: 3.82 | G3: =E3*60/F3 -> 24.659686
A4: 45810.292 | B4: 3 | C4: 41.332180445326756, 69.26923046640113 | D4: 41.33927686915818, 69.25398056929649 | E4: 1.5 | F4: 2.63 | G4: =E4*60/F4 -> 34.220532
A5: 45810.292 | B5: 4 | C5: 41.33927686915818, 69.25398056929649 | D5: 41.341917122525444, 69.23651333737624 | E5: 1.5 | F5: 2.38 | G5: =E5*60/F5 -> 37.815126
A6: 45810.292 | B6: 5 | C6: 41.341917122525444, 69.23651333737624 | D6: 41.3355661273189, 69.22092813210918 | E6: 1.52 | F6: 2.7 | G6: =E6*60/F6 -> 33.777778
A7: 45810.292 | B7: 6 | C7: 41.3355661273189, 69.22092813210918 | D7: 41.32435077486925, 69.210996318545 | E7: 1.5 | F7: 2.48 | G7: =E7*60/F7 -> 36.290323
A8: 45810.292 | B8: 7 | C8: 41.32435077486925, 69.210996318545 | D8: 41.31115833391201, 69.2074172881025 | E8: 1.54 | F8: 2.5 | G8: =E8*60/F8 -> 36.96
A9: 45810.292 | B9: 8 | C9: 41.31115833391201, 69.2074172881025 | D9: 41.29858235062461, 69.21262191402178 | E9: 1.54 | F9: 2.68 | G9: =E9*60/F9 -> 34.477612
A10: 45810.292 | B10: 9 | C10: 41.29858235062461, 69.21262191402178 | D10: 41.289787898161364, 69.2265988055295 | E10: 1.52 | F10: 2.6 | G10: =E10*60/F10 -> 35.076923
A11: 45810.292 | B11: 10 | C11: 41.289787898161364, 69.2265988055295 | D11: 41.28106476890745, 69.24026245064472 | E11: 1.5 | F11: 2.75 | G11: =E11*60/F11 -> 32.727273
A12: 45810.292 | B12: 11 | C12: 41.28106476890745, 69.24026245064472 | D12: 41.28064845978927, 69.25601908163817 | E12: 1.48 | F12: 2.22 | G12: =E12*60/F12 -> 40
A13: 45810.292 | B13: 12 | C13: 41.28064845978927, 69.25601908163817 | D13: 41.28687171940977, 69.27143808322909 | E13: 1.46 | F13: 2.68 | G13: =E13*60/F13 -> 32.686567
... A1509: 45810.792 | B1509: 58 | C1509: 41.32310314706941, 69.28241762019745 | D1509: 41.33644779653366, 69.28519116101587 | E1509: 1.5 | F1509: 4.17 | G1509: =E1509*60/F1509 -> 21.582734

Sheet Tuesday
A1: timestamp | B1: route_id | C1: start | D1: end | E1: distance_km | F1: duration_in_traffic_min | G1: speed_km/h
A2: 45804.292 | B2: 1 | C2: 41.32516738436008, 69.30379886174566 | D2: 41.327552032716724, 69.28609735456061 | E2: 1.53 | F2: 2.78 | G2: =E2*60/F2 -> 33.021583
A3: 45804.292 | B3: 2 | C3: 41.327552032716724, 69.28609735456061 | D3: 41.332180445326756, 69.26923046640113 | E3: 1.57 | F3: 3.93 | G3: =E3*60/F3 -> 23.969466
A4: 45804.292 | B4: 3 | C4: 41.332180445326756, 69.26923046640113 | D4: 41.33927686915818, 69.25398056929649 | E4: 1.5 | F4: 2.62 | G4: =E4*60/F4 -> 34.351145
A5: 45804.292 | B5: 4 | C5: 41.33927686915818, 69.25398056929649 | D5: 41.341917122525444, 69.23651333737624 | E5: 1.5 | F5: 2.43 | G5: =E5*60/F5 -> 37.037037
A6: 45804.292 | B6: 5 | C6: 41.341917122525444, 69.23651333737624 | D6: 41.3355661273189, 69.22092813210918 | E6: 1.52 | F6: 2.6 | G6: =E6*60/F6 -> 35.076923
A7: 45804.292 | B7: 6 | C7: 41.3355661273189, 69.22092813210918 | D7: 41.32435077486925, 69.210996318545 | E7: 1.5 | F7: 2.42 | G7: =E7*60/F7 -> 37.190083
A8: 45804.292 | B8: 7 | C8: 41.32435077486925, 69.210996318545 | D8: 41.31115833391201, 69.2074172881025 | E8: 1.54 | F8: 2.52 | G8: =E8*60/F8 -> 36.666667
A9: 45804.292 | B9: 8 | C9: 41.31115833391201, 69.2074172881025 | D9: 41.29858235062461, 69.21262191402178 | E9: 1.54 | F9: 2.77 | G9: =E9*60/F9 -> 33.357401
A10: 45804.292 | B10: 9 | C10: 41.29858235062461, 69.21262191402178 | D10: 41.289787898161364, 69.2265988055295 | E10: 1.52 | F10: 2.82 | G10: =E10*60/F10 -> 32.340426
A11: 45804.292 | B11: 10 | C11: 41.289787898161364, 69.2265988055295 | D11: 41.28106476890745, 69.24026245064472 | E11: 1.5 | F11: 2.82 | G11: =E11*60/F11 -> 31.914894
A12: 45804.292 | B12: 11 | C12: 41.28106476890745, 69.24026245064472 | D12: 41.28064845978927, 69.25601908163817 | E12: 1.48 | F12: 2.23 | G12: =E12*60/F12 -> 39.820628
A13: 45804.292 | B13: 12 | C13: 41.28064845978927, 69.25601908163817 | D13: 41.28687171940977, 69.27143808322909 | E13: 1.46 | F13: 2.58 | G13: =E13*60/F13 -> 33.953488
... A1509: 45804.792 | B1509: 58 | C1509: 41.32310314706941, 69.28241762019745 | D1509: 41.33644779653366, 69.28519116101587 | E1509: 1.5 | F1509: 4.72 | G1509: =E1509*60/F1509 -> 19.067797

Sheet Wednesday
A1: timestamp | B1: route_id | C1: start | D1: end | E1: distance_km | F1: duration_in_traffic_min | G1: speed_km/h
A2: 45805.292 | B2: 1 | C2: 41.32516738436008, 69.30379886174566 | D2: 41.327552032716724, 69.28609735456061 | E2: 1.53 | F2: 2.73 | G2: =E2*60/F2 -> 33.626374
A3: 45805.292 | B3: 2 | C3: 41.327552032716724, 69.28609735456061 | D3: 41.332180445326756, 69.26923046640113 | E3: 1.57 | F3: 3.98 | G3: =E3*60/F3 -> 23.668342
A4: 45805.292 | B4: 3 | C4: 41.332180445326756, 69.26923046640113 | D4: 41.33927686915818, 69.25398056929649 | E4: 1.5 | F4: 2.63 | G4: =E4*60/F4 -> 34.220532
A5: 45805.292 | B5: 4 | C5: 41.33927686915818, 69.25398056929649 | D5: 41.341917122525444, 69.23651333737624 | E5: 1.5 | F5: 2.35 | G5: =E5*60/F5 -> 38.297872
A6: 45805.292 | B6: 5 | C6: 41.341917122525444, 69.23651333737624 | D6: 41.3355661273189, 69.22092813210918 | E6: 1.52 | F6: 2.57 | G6: =E6*60/F6 -> 35.486381
A7: 45805.292 | B7: 6 | C7: 41.3355661273189, 69.22092813210918 | D7: 41.32435077486925, 69.210996318545 | E7: 1.5 | F7: 2.32 | G7: =E7*60/F7 -> 38.793103
A8: 45805.292 | B8: 7 | C8: 41.32435077486925, 69.210996318545 | D8: 41.31115833391201, 69.2074172881025 | E8: 1.54 | F8: 2.4 | G8: =E8*60/F8 -> 38.5
A9: 45805.292 | B9: 8 | C9: 41.31115833391201, 69.2074172881025 | D9: 41.29858235062461, 69.21262191402178 | E9: 1.54 | F9: 2.73 | G9: =E9*60/F9 -> 33.846154
A10: 45805.292 | B10: 9 | C10: 41.29858235062461, 69.21262191402178 | D10: 41.289787898161364, 69.2265988055295 | E10: 1.52 | F10: 2.65 | G10: =E10*60/F10 -> 34.415094
A11: 45805.292 | B11: 10 | C11: 41.289787898161364, 69.2265988055295 | D11: 41.28106476890745, 69.24026245064472 | E11: 1.5 | F11: 2.8 | G11: =E11*60/F11 -> 32.142857
A12: 45805.292 | B12: 11 | C12: 41.28106476890745, 69.24026245064472 | D12: 41.28064845978927, 69.25601908163817 | E12: 1.48 | F12: 2.17 | G12: =E12*60/F12 -> 40.921659
A13: 45805.292 | B13: 12 | C13: 41.28064845978927, 69.25601908163817 | D13: 41.28687171940977, 69.27143808322909 | E13: 1.46 | F13: 2.6 | G13: =E13*60/F13 -> 33.692308
... A1509: 45805.792 | B1509: 58 | C1509: 41.32310314706941, 69.28241762019745 | D1509: 41.33644779653366, 69.28519116101587 | E1509: 1.5 | F1509: 5.07 | G1509: =E1509*60/F1509 -> 17.751479

Sheet Thursday
A1: timestamp | B1: route_id | C1: start | D1: end | E1: distance_km | F1: duration_in_traffic_min | G1: speed_km/h
A2: 45806.292 | B2: 1 | C2: 41.32516738436008, 69.30379886174566 | D2: 41.327552032716724, 69.28609735456061 | E2: 1.53 | F2: 2.88 | G2: =E2*60/F2 -> 31.875
A3: 45806.292 | B3: 2 | C3: 41.327552032716724, 69.28609735456061 | D3: 41.332180445326756, 69.26923046640113 | E3: 1.57 | F3: 3.75 | G3: =E3*60/F3 -> 25.12
A4: 45806.292 | B4: 3 | C4: 41.332180445326756, 69.26923046640113 | D4: 41.33927686915818, 69.25398056929649 | E4: 1.5 | F4: 2.67 | G4: =E4*60/F4 -> 33.707865
A5: 45806.292 | B5: 4 | C5: 41.33927686915818, 69.25398056929649 | D5: 41.341917122525444, 69.23651333737624 | E5: 1.5 | F5: 2.43 | G5: =E5*60/F5 -> 37.037037
A6: 45806.292 | B6: 5 | C6: 41.341917122525444, 69.23651333737624 | D6: 41.3355661273189, 69.22092813210918 | E6: 1.52 | F6: 2.78 | G6: =E6*60/F6 -> 32.805755
A7: 45806.292 | B7: 6 | C7: 41.3355661273189, 69.22092813210918 | D7: 41.32435077486925, 69.210996318545 | E7: 1.5 | F7: 2.45 | G7: =E7*60/F7 -> 36.734694
A8: 45806.292 | B8: 7 | C8: 41.32435077486925, 69.210996318545 | D8: 41.31115833391201, 69.2074172881025 | E8: 1.54 | F8: 2.45 | G8: =E8*60/F8 -> 37.714286
A9: 45806.292 | B9: 8 | C9: 41.31115833391201, 69.2074172881025 | D9: 41.29858235062461, 69.21262191402178 | E9: 1.54 | F9: 2.8 | G9: =E9*60/F9 -> 33
A10: 45806.292 | B10: 9 | C10: 41.29858235062461, 69.21262191402178 | D10: 41.289787898161364, 69.2265988055295 | E10: 1.52 | F10: 2.67 | G10: =E10*60/F10 -> 34.157303
A11: 45806.292 | B11: 10 | C11: 41.289787898161364, 69.2265988055295 | D11: 41.28106476890745, 69.24026245064472 | E11: 1.5 | F11: 2.77 | G11: =E11*60/F11 -> 32.490975
A12: 45806.292 | B12: 11 | C12: 41.28106476890745, 69.24026245064472 | D12: 41.28064845978927, 69.25601908163817 | E12: 1.48 | F12: 2.27 | G12: =E12*60/F12 -> 39.118943
A13: 45806.292 | B13: 12 | C13: 41.28064845978927, 69.25601908163817 | D13: 41.28687171940977, 69.27143808322909 | E13: 1.46 | F13: 2.65 | G13: =E13*60/F13 -> 33.056604
... A1509: 45806.792 | B1509: 58 | C1509: 41.32310314706941, 69.28241762019745 | D1509: 41.33644779653366, 69.28519116101587 | E1509: 1.5 | F1509: 4.8 | G1509: =E1509*60/F1509 -> 18.75

Sheet Friday
A1: timestamp | B1: route_id | C1: start | D1: end | E1: distance_km | F1: duration_in_traffic_min | G1: speed_km/h
A2: 45807.292 | B2: 1 | C2: 41.32516738436008, 69.30379886174566 | D2: 41.327552032716724, 69.28609735456061 | E2: 1.53 | F2: 2.82 | G2: =E2*60/F2 -> 32.553191
A3: 45807.292 | B3: 2 | C3: 41.327552032716724, 69.28609735456061 | D3: 41.332180445326756, 69.26923046640113 | E3: 1.57 | F3: 4.03 | G3: =E3*60/F3 -> 23.37469
A4: 45807.292 | B4: 3 | C4: 41.332180445326756, 69.26923046640113 | D4: 41.33927686915818, 69.25398056929649 | E4: 1.5 | F4: 2.73 | G4: =E4*60/F4 -> 32.967033
A5: 45807.292 | B5: 4 | C5: 41.33927686915818, 69.25398056929649 | D5: 41.341917122525444, 69.23651333737624 | E5: 1.5 | F5: 2.57 | G5: =E5*60/F5 -> 35.019455
A6: 45807.292 | B6: 5 | C6: 41.341917122525444, 69.23651333737624 | D6: 41.3355661273189, 69.22092813210918 | E6: 1.52 | F6: 2.68 | G6: =E6*60/F6 -> 34.029851
A7: 45807.292 | B7: 6 | C7: 41.3355661273189, 69.22092813210918 | D7: 41.32435077486925, 69.210996318545 | E7: 1.5 | F7: 2.3 | G7: =E7*60/F7 -> 39.130435
A8: 45807.292 | B8: 7 | C8: 41.32435077486925, 69.210996318545 | D8: 41.31115833391201, 69.2074172881025 | E8: 1.54 | F8: 2.38 | G8: =E8*60/F8 -> 38.823529
A9: 45807.292 | B9: 8 | C9: 41.31115833391201, 69.2074172881025 | D9: 41.29858235062461, 69.21262191402178 | E9: 1.54 | F9: 2.67 | G9: =E9*60/F9 -> 34.606742
A10: 45807.292 | B10: 9 | C10: 41.29858235062461, 69.21262191402178 | D10: 41.289787898161364, 69.2265988055295 | E10: 1.52 | F10: 2.63 | G10: =E10*60/F10 -> 34.676806
A11: 45807.292 | B11: 10 | C11: 41.289787898161364, 69.2265988055295 | D11: 41.28106476890745, 69.24026245064472 | E11: 1.5 | F11: 2.75 | G11: =E11*60/F11 -> 32.727273
A12: 45807.292 | B12: 11 | C12: 41.28106476890745, 69.24026245064472 | D12: 41.28064845978927, 69.25601908163817 | E12: 1.48 | F12: 2.2 | G12: =E12*60/F12 -> 40.363636
A13: 45807.292 | B13: 12 | C13: 41.28064845978927, 69.25601908163817 | D13: 41.28687171940977, 69.27143808322909 | E13: 1.46 | F13: 2.6 | G13: =E13*60/F13 -> 33.692308
... A1509: 45807.792 | B1509: 58 | C1509: 41.32310314706941, 69.28241762019745 | D1509: 41.33644779653366, 69.28519116101587 | E1509: 1.5 | F1509: 4.5 | G1509: =E1509*60/F1509 -> 20

Sheet Saturday
A1: timestamp | B1: route_id | C1: start | D1: end | E1: distance_km | F1: duration_in_traffic_min | G1: speed_km/h
A2: 45808.292 | B2: 1 | C2: 41.32516738436008, 69.30379886174566 | D2: 41.327552032716724, 69.28609735456061 | E2: 1.53 | F2: 2.75 | G2: =E2*60/F2 -> 33.381818
A3: 45808.292 | B3: 2 | C3: 41.327552032716724, 69.28609735456061 | D3: 41.332180445326756, 69.26923046640113 | E3: 1.57 | F3: 3.78 | G3: =E3*60/F3 -> 24.920635
A4: 45808.292 | B4: 3 | C4: 41.332180445326756, 69.26923046640113 | D4: 41.33927686915818, 69.25398056929649 | E4: 1.5 | F4: 2.6 | G4: =E4*60/F4 -> 34.615385
A5: 45808.292 | B5: 4 | C5: 41.33927686915818, 69.25398056929649 | D5: 41.341917122525444, 69.23651333737624 | E5: 1.5 | F5: 2.28 | G5: =E5*60/F5 -> 39.473684
A6: 45808.292 | B6: 5 | C6: 41.341917122525444, 69.23651333737624 | D6: 41.3355661273189, 69.22092813210918 | E6: 1.52 | F6: 2.67 | G6: =E6*60/F6 -> 34.157303
A7: 45808.292 | B7: 6 | C7: 41.3355661273189, 69.22092813210918 | D7: 41.32435077486925, 69.210996318545 | E7: 1.5 | F7: 2.42 | G7: =E7*60/F7 -> 37.190083
A8: 45808.292 | B8: 7 | C8: 41.32435077486925, 69.210996318545 | D8: 41.31115833391201, 69.2074172881025 | E8: 1.54 | F8: 2.58 | G8: =E8*60/F8 -> 35.813953
A9: 45808.292 | B9: 8 | C9: 41.31115833391201, 69.2074172881025 | D9: 41.29858235062461, 69.21262191402178 | E9: 1.54 | F9: 2.72 | G9: =E9*60/F9 -> 33.970588
A10: 45808.292 | B10: 9 | C10: 41.29858235062461, 69.21262191402178 | D10: 41.289787898161364, 69.2265988055295 | E10: 1.52 | F10: 2.63 | G10: =E10*60/F10 -> 34.676806
A11: 45808.292 | B11: 10 | C11: 41.289787898161364, 69.2265988055295 | D11: 41.28106476890745, 69.24026245064472 | E11: 1.5 | F11: 2.72 | G11: =E11*60/F11 -> 33.088235
A12: 45808.292 | B12: 11 | C12: 41.28106476890745, 69.24026245064472 | D12: 41.28064845978927, 69.25601908163817 | E12: 1.48 | F12: 1.98 | G12: =E12*60/F12 -> 44.848485
A13: 45808.292 | B13: 12 | C13: 41.28064845978927, 69.25601908163817 | D13: 41.28687171940977, 69.27143808322909 | E13: 1.46 | F13: 2.48 | G13: =E13*60/F13 -> 35.322581
... A1509: 45808.792 | B1509: 58 | C1509: 41.32310314706941, 69.28241762019745 | D1509: 41.33644779653366, 69.28519116101587 | E1509: 1.5 | F1509: 3.78 | G1509: =E1509*60/F1509 -> 23.809524

Sheet Sunday
A1: timestamp | B1: route_id | C1: start | D1: end | E1: distance_km | F1: duration_in_traffic_min | G1: speed_km/h
A2: 45809.292 | B2: 1 | C2: 41.32516738436008, 69.30379886174566 | D2: 41.327552032716724, 69.28609735456061 | E2: 1.53 | F2: 2.75 | G2: =E2*60/F2 -> 33.381818
A3: 45809.292 | B3: 2 | C3: 41.327552032716724, 69.28609735456061 | D3: 41.332180445326756, 69.26923046640113 | E3: 1.57 | F3: 3.57 | G3: =E3*60/F3 -> 26.386555
A4: 45809.292 | B4: 3 | C4: 41.332180445326756, 69.26923046640113 | D4: 41.33927686915818, 69.25398056929649 | E4: 1.5 | F4: 2.55 | G4: =E4*60/F4 -> 35.294118
A5: 45809.292 | B5: 4 | C5: 41.33927686915818, 69.25398056929649 | D5: 41.341917122525444, 69.23651333737624 | E5: 1.5 | F5: 2.22 | G5: =E5*60/F5 -> 40.540541
A6: 45809.292 | B6: 5 | C6: 41.341917122525444, 69.23651333737624 | D6: 41.3355661273189, 69.22092813210918 | E6: 1.52 | F6: 2.48 | G6: =E6*60/F6 -> 36.774194
A7: 45809.292 | B7: 6 | C7: 41.3355661273189, 69.22092813210918 | D7: 41.32435077486925, 69.210996318545 | E7: 1.5 | F7: 2.18 | G7: =E7*60/F7 -> 41.284404
A8: 45809.292 | B8: 7 | C8: 41.32435077486925, 69.210996318545 | D8: 41.31115833391201, 69.2074172881025 | E8: 1.54 | F8: 2.42 | G8: =E8*60/F8 -> 38.181818
A9: 45809.292 | B9: 8 | C9: 41.31115833391201, 69.2074172881025 | D9: 41.29858235062461, 69.21262191402178 | E9: 1.54 | F9: 2.67 | G9: =E9*60/F9 -> 34.606742
A10: 45809.292 | B10: 9 | C10: 41.29858235062461, 69.21262191402178 | D10: 41.289787898161364, 69.2265988055295 | E10: 1.52 | F10: 2.55 | G10: =E10*60/F10 -> 35.764706
A11: 45809.292 | B11: 10 | C11: 41.289787898161364, 69.2265988055295 | D11: 41.28106476890745, 69.24026245064472 | E11: 1.5 | F11: 2.55 | G11: =E11*60/F11 -> 35.294118
A12: 45809.292 | B12: 11 | C12: 41.28106476890745, 69.24026245064472 | D12: 41.28064845978927, 69.25601908163817 | E12: 1.48 | F12: 2.1 | G12: =E12*60/F12 -> 42.285714
A13: 45809.292 | B13: 12 | C13: 41.28064845978927, 69.25601908163817 | D13: 41.28687171940977, 69.27143808322909 | E13: 1.46 | F13: 2.38 | G13: =E13*60/F13 -> 36.806723
... A1509: 45809.792 | B1509: 58 | C1509: 41.32310314706941, 69.28241762019745 | D1509: 41.33644779653366, 69.28519116101587 | E1509: 1.5 | F1509: 3.42 | G1509: =E1509*60/F1509 -> 26.315789

Sheet TT
B1: TT
A2: route_id/Time interval | B2: 0.29166667 | D2: 0.30208333 | F2: 0.3125 | H2: 0.32291667 | J2: 0.33333333 | L2: 0.34375 | N2: 0.35416667 | P2: 0.36458333 | R2: 0.375 | T2: 0.38541667 | V2: 0.39583333 | X2: 0.40625 | Z2: 0.41666667 | AB2: 0.66666667 | AD2: 0.67708333 | AF2: 0.6875 | AH2: 0.69791667 | AJ2: 0.70833333 | AL2: 0.71875 | AN2: 0.72916667 | AP2: 0.73958333 | AR2: 0.75 | AT2: 0.76041667 | AV2: 0.77083333 | AX2: 0.78125 | AZ2: 0.79166667 | BB2: route_id/Time interval | BC2: TT
B3: average | C3: median | D3: average | E3: median | F3: average | G3: median | H3: average | I3: median | J3: average | K3: median | L3: average | M3: median | N3: average | O3: median | P3: average | Q3: median | R3: average | S3: median | T3: average | U3: median | V3: average | W3: median | X3: average | Y3: median | Z3: average | AA3: median | AB3: average | AC3: median | AD3: average | AE3: median | AF3: average | AG3: median | AH3: average | AI3: median | AJ3: average | AK3: median | AL3: average | AM3: median | AN3: average | AO3: median | AP3: average | AQ3: median | AR3: average | AS3: median | AT3: average | AU3: median | AV3: average | AW3: median | AX3: average | AY3: median | AZ3: average | BA3: median | BC3: Average | BD3: Median
A4: 1 | B4: =AVERAGE(Monday!F2,Tuesday!F2,Wednesday!F2,Thursday!F2,Friday!F2) -> 2.792 | C4: =MEDIAN(Monday!F2,Tuesday!F2,Wednesday!F2,Thursday!F2,Friday!F2) -> 2.78 | D4: =AVERAGE(Monday!F60,Tuesday!F60,Wednesday!F60,Thursday!F60,Friday!F60) -> 2.824 | E4: =MEDIAN(Monday!F60,Tuesday!F60,Wednesday!F60,Thursday!F60,Friday!F60) -> 2.82 | F4: =AVERAGE(Monday!F118,Tuesday!F118,Wednesday!F118,Thursday!F118,Friday!F118) -> 2.884 | G4: =MEDIAN(Monday!F118,Tuesday!F118,Wednesday!F118,Thursday!F118,Friday!F118) -> 2.88 | H4: =AVERAGE(Monday!F176,Tuesday!F176,Wednesday!F176,Thursday!F176,Friday!F176) -> 2.932 | I4: =MEDIAN(Monday!F176,Tuesday!F176,Wednesday!F176,Thursday!F176,Friday!F176) -> 2.93 | J4: =AVERAGE(Monday!F234,Tuesday!F234,Wednesday!F234,Thursday!F234,Friday!F234) -> 3.058 | K4: =MEDIAN(Monday!F234,Tuesday!F234,Wednesday!F234,Thursday!F234,Friday!F234) -> 3.03 | L4: =AVERAGE(Monday!F292,Tuesday!F292,Wednesday!F292,Thursday!F292,Friday!F292) -> 3.058 | M4: =MEDIAN(Monday!F292,Tuesday!F292,Wednesday!F292,Thursday!F292,Friday!F292) -> 3.1 | N4: =AVERAGE(Monday!F350,Tuesday!F350,Wednesday!F350,Thursday!F350,Friday!F350) -> 3.128 | O4: =MEDIAN(Monday!F350,Tuesday!F350,Wednesday!F350,Thursday!F350,Friday!F350) -> 3.12 | P4: =AVERAGE(Monday!F408,Tuesday!F408,Wednesday!F408,Thursday!F408,Friday!F408) -> 3.134 | Q4: =MEDIAN(Monday!F408,Tuesday!F408,Wednesday!F408,Thursday!F408,Friday!F408) -> 3.17 | R4: =AVERAGE(Monday!F466,Tuesday!F466,Wednesday!F466,Thursday!F466,Friday!F466) -> 3.134 | S4: =MEDIAN(Monday!F466,Tuesday!F466,Wednesday!F466,Thursday!F466,Friday!F466) -> 3.15 | T4: =AVERAGE(Monday!F524,Tuesday!F524,Wednesday!F524,Thursday!F524,Friday!F524) -> 3.146 | U4: =MEDIAN(Monday!F524,Tuesday!F524,Wednesday!F524,Thursday!F524,Friday!F524) -> 3.15 | V4: =AVERAGE(Monday!F582,Tuesday!F582,Wednesday!F582,Thursday!F582,Friday!F582) -> 3.156 | W4: =MEDIAN(Monday!F582,Tuesday!F582,Wednesday!F582,Thursday!F582,Friday!F582) -> 3.13 | X4: =AVERAGE(Monday!F640,Tuesday!F640,Wednesday!F640,Thursday!F640,Friday!F640) -> 3.198 | Y4: =MEDIAN(Monday!F640,Tuesday!F640,Wednesday!F640,Thursday!F640,Friday!F640) -> 3.13 | Z4: =AVERAGE(Monday!F698,Tuesday!F698,Wednesday!F698,Thursday!F698,Friday!F698) -> 3.172 | AA4: =MEDIAN(Monday!F698,Tuesday!F698,Wednesday!F698,Thursday!F698,Friday!F698) -> 3.15 | AB4: =AVERAGE(Monday!F756,Tuesday!F756,Wednesday!F756,Thursday!F756,Friday!F756) -> 3.332 | AC4: =MEDIAN(Monday!F756,Tuesday!F756,Wednesday!F756,Thursday!F756,Friday!F756) -> 3.27 | AD4: =AVERAGE(Monday!F814,Tuesday!F814,Wednesday!F814,Thursday!F814,Friday!F814) -> 3.4 | AE4: =MEDIAN(Monday!F814,Tuesday!F814,Wednesday!F814,Thursday!F814,Friday!F814) -> 3.48 | AF4: =AVERAGE(Monday!F872,Tuesday!F872,Wednesday!F872,Thursday!F872,Friday!F872) -> 3.3 | AG4: =MEDIAN(Monday!F872,Tuesday!F872,Wednesday!F872,Thursday!F872,Friday!F872) -> 3.32 | AH4: =AVERAGE(Monday!F930,Tuesday!F930,Wednesday!F930,Thursday!F930,Friday!F930) -> 3.434 | AI4: =MEDIAN(Monday!F930,Tuesday!F930,Wednesday!F930,Thursday!F930,Friday!F930) -> 3.48 | AJ4: =AVERAGE(Monday!F988,Tuesday!F988,Wednesday!F988,Thursday!F988,Friday!F988) -> 3.46 | AK4: =MEDIAN(Monday!F988,Tuesday!F988,Wednesday!F988,Thursday!F988,Friday!F988) -> 3.45 | AL4: =AVERAGE(Monday!F1046,Tuesday!F1046,Wednesday!F1046,Thursday!F1046,Friday!F1046) -> 3.386 | AM4: =MEDIAN(Monday!F1046,Tuesday!F1046,Wednesday!F1046,Thursday!F1046,Friday!F1046) -> 3.4 | AN4: =AVERAGE(Monday!F1104,Tuesday!F1104,Wednesday!F1104,Thursday!F1104,Friday!F1104) -> 3.356 | AO4: =MEDIAN(Monday!F1104,Tuesday!F1104,Wednesday!F1104,Thursday!F1104,Friday!F1104) -> 3.37 | AP4: =AVERAGE(Monday!F1162,Tuesday!F1162,Wednesday!F1162,Thursday!F1162,Friday!F1162) -> 3.554 | AQ4: =MEDIAN(Monday!F1162,Tuesday!F1162,Wednesday!F1162,Thursday!F1162,Friday!F1162) -> 3.53 | AR4: =AVERAGE(Monday!F1220,Tuesday!F1220,Wednesday!F1220,Thursday!F1220,Friday!F1220) -> 3.58 | AS4: =MEDIAN(Monday!F1220,Tuesday!F1220,Wednesday!F1220,Thursday!F1220,Friday!F1220) -> 3.65 | AT4: =AVERAGE(Monday!F1278,Tuesday!F1278,Wednesday!F1278,Thursday!F1278,Friday!F1278) -> 3.624 | AU4: =MEDIAN(Monday!F1278,Tuesday!F1278,Wednesday!F1278,Thursday!F1278,Friday!F1278) -> 3.67 | AV4: =AVERAGE(Monday!F1336,Tuesday!F1336,Wednesday!F1336,Thursday!F1336,Friday!F1336) -> 3.752 | AW4: =MEDIAN(Monday!F1336,Tuesday!F1336,Wednesday!F1336,Thursday!F1336,Friday!F1336) -> 3.55 | AX4: =AVERAGE(Monday!F1394,Tuesday!F1394,Wednesday!F1394,Thursday!F1394,Friday!F1394) -> 3.39 | AY4: =MEDIAN(Monday!F1394,Tuesday!F1394,Wednesday!F1394,Thursday!F1394,Friday!F1394) -> 3.4 | AZ4: =AVERAGE(Monday!F1452,Tuesday!F1452,Wednesday!F1452,Thursday!F1452,Friday!F1452) -> 3.288 | BA4: =MEDIAN(Monday!F1452,Tuesday!F1452,Wednesday!F1452,Thursday!F1452,Friday!F1452) -> 3.28 | BB4: 1 | BC4: =AVERAGE(B4,D4,F4,H4,J4,L4,N4,P4,R4,T4,V4,X4,Z4,AB4,AD4,AF4,AH4,AJ4,AL4,AN4,AP4,AR4,AT4,AV4,AX4,AZ4) -> 3.2489231 | BD4: =MEDIAN(C4,E4,G4,I4,K4,M4,O4,Q4,S4,U4,W4,Y4,AA4,AC4,AE4,AG4,AI4,AK4,AM4,AO4,AQ4,AS4,AU4,AW4,AY4,BA4) -> 3.22
A5: 2 | B5: =AVERAGE(Monday!F3,Tuesday!F3,Wednesday!F3,Thursday!F3,Friday!F3) -> 3.902 | C5: =MEDIAN(Monday!F3,Tuesday!F3,Wednesday!F3,Thursday!F3,Friday!F3) -> 3.93 | D5: =AVERAGE(Monday!F61,Tuesday!F61,Wednesday!F61,Thursday!F61,Friday!F61) -> 3.996 | E5: =MEDIAN(Monday!F61,Tuesday!F61,Wednesday!F61,Thursday!F61,Friday!F61) -> 4.05 | F5: =AVERAGE(Monday!F119,Tuesday!F119,Wednesday!F119,Thursday!F119,Friday!F119) -> 4.258 | G5: =MEDIAN(Monday!F119,Tuesday!F119,Wednesday!F119,Thursday!F119,Friday!F119) -> 4.32 | H5: =AVERAGE(Monday!F177,Tuesday!F177,Wednesday!F177,Thursday!F177,Friday!F177) -> 4.508 | I5: =MEDIAN(Monday!F177,Tuesday!F177,Wednesday!F177,Thursday!F177,Friday!F177) -> 4.52 | J5: =AVERAGE(Monday!F235,Tuesday!F235,Wednesday!F235,Thursday!F235,Friday!F235) -> 4.78 | K5: =MEDIAN(Monday!F235,Tuesday!F235,Wednesday!F235,Thursday!F235,Friday!F235) -> 4.75 | L5: =AVERAGE(Monday!F293,Tuesday!F293,Wednesday!F293,Thursday!F293,Friday!F293) -> 4.904 | M5: =MEDIAN(Monday!F293,Tuesday!F293,Wednesday!F293,Thursday!F293,Friday!F293) -> 4.95 | N5: =AVERAGE(Monday!F351,Tuesday!F351,Wednesday!F351,Thursday!F351,Friday!F351) -> 5.264 | O5: =MEDIAN(Monday!F351,Tuesday!F351,Wednesday!F351,Thursday!F351,Friday!F351) -> 5.3 | P5: =AVERAGE(Monday!F409,Tuesday!F409,Wednesday!F409,Thursday!F409,Friday!F409) -> 5.464 | Q5: =MEDIAN(Monday!F409,Tuesday!F409,Wednesday!F409,Thursday!F409,Friday!F409) -> 5.55 | R5: =AVERAGE(Monday!F467,Tuesday!F467,Wednesday!F467,Thursday!F467,Friday!F467) -> 5.106 | S5: =MEDIAN(Monday!F467,Tuesday!F467,Wednesday!F467,Thursday!F467,Friday!F467) -> 5.13 | T5: =AVERAGE(Monday!F525,Tuesday!F525,Wednesday!F525,Thursday!F525,Friday!F525) -> 4.852 | U5: =MEDIAN(Monday!F525,Tuesday!F525,Wednesday!F525,Thursday!F525,Friday!F525) -> 4.87 | V5: =AVERAGE(Monday!F583,Tuesday!F583,Wednesday!F583,Thursday!F583,Friday!F583) -> 5.022 | W5: =MEDIAN(Monday!F583,Tuesday!F583,Wednesday!F583,Thursday!F583,Friday!F583) -> 5.02 | X5: =AVERAGE(Monday!F641,Tuesday!F641,Wednesday!F641,Thursday!F641,Friday!F641) -> 4.966 | Y5: =MEDIAN(Monday!F641,Tuesday!F641,Wednesday!F641,Thursday!F641,Friday!F641) -> 4.97 | Z5: =AVERAGE(Monday!F699,Tuesday!F699,Wednesday!F699,Thursday!F699,Friday!F699) -> 4.992 | AA5: =MEDIAN(Monday!F699,Tuesday!F699,Wednesday!F699,Thursday!F699,Friday!F699) -> 4.92 | AB5: =AVERAGE(Monday!F757,Tuesday!F757,Wednesday!F757,Thursday!F757,Friday!F757) -> 5.622 | AC5: =MEDIAN(Monday!F757,Tuesday!F757,Wednesday!F757,Thursday!F757,Friday!F757) -> 5.63 | AD5: =AVERAGE(Monday!F815,Tuesday!F815,Wednesday!F815,Thursday!F815,Friday!F815) -> 5.664 | AE5: =MEDIAN(Monday!F815,Tuesday!F815,Wednesday!F815,Thursday!F815,Friday!F815) -> 5.7 | AF5: =AVERAGE(Monday!F873,Tuesday!F873,Wednesday!F873,Thursday!F873,Friday!F873) -> 5.85 | AG5: =MEDIAN(Monday!F873,Tuesday!F873,Wednesday!F873,Thursday!F873,Friday!F873) -> 5.75 | AH5: =AVERAGE(Monday!F931,Tuesday!F931,Wednesday!F931,Thursday!F931,Friday!F931) -> 5.786 | AI5: =MEDIAN(Monday!F931,Tuesday!F931,Wednesday!F931,Thursday!F931,Friday!F931) -> 6.02 | AJ5: =AVERAGE(Monday!F989,Tuesday!F989,Wednesday!F989,Thursday!F989,Friday!F989) -> 5.97 | AK5: =MEDIAN(Monday!F989,Tuesday!F989,Wednesday!F989,Thursday!F989,Friday!F989) -> 6.03 | AL5: =AVERAGE(Monday!F1047,Tuesday!F1047,Wednesday!F1047,Thursday!F1047,Friday!F1047) -> 5.75 | AM5: =MEDIAN(Monday!F1047,Tuesday!F1047,Wednesday!F1047,Thursday!F1047,Friday!F1047) -> 5.77 | AN5: =AVERAGE(Monday!F1105,Tuesday!F1105,Wednesday!F1105,Thursday!F1105,Friday!F1105) -> 5.934 | AO5: =MEDIAN(Monday!F1105,Tuesday!F1105,Wednesday!F1105,Thursday!F1105,Friday!F1105) -> 5.95 | AP5: =AVERAGE(Monday!F1163,Tuesday!F1163,Wednesday!F1163,Thursday!F1163,Friday!F1163) -> 7.102 | AQ5: =MEDIAN(Monday!F1163,Tuesday!F1163,Wednesday!F1163,Thursday!F1163,Friday!F1163) -> 6.65 | AR5: =AVERAGE(Monday!F1221,Tuesday!F1221,Wednesday!F1221,Thursday!F1221,Friday!F1221) -> 7.242 | AS5: =MEDIAN(Monday!F1221,Tuesday!F1221,Wednesday!F1221,Thursday!F1221,Friday!F1221) -> 7.22 | AT5: =AVERAGE(Monday!F1279,Tuesday!F1279,Wednesday!F1279,Thursday!F1279,Friday!F1279) -> 6.84 | AU5: =MEDIAN(Monday!F1279,Tuesday!F1279,Wednesday!F1279,Thursday!F1279,Friday!F1279) -> 6.6 | AV5: =AVERAGE(Monday!F1337,Tuesday!F1337,Wednesday!F1337,Thursday!F1337,Friday!F1337) -> 7.032 | AW5: =MEDIAN(Monday!F1337,Tuesday!F1337,Wednesday!F1337,Thursday!F1337,Friday!F1337) -> 7.07 | AX5: =AVERAGE(Monday!F1395,Tuesday!F1395,Wednesday!F1395,Thursday!F1395,Friday!F1395) -> 7.048 | AY5: =MEDIAN(Monday!F1395,Tuesday!F1395,Wednesday!F1395,Thursday!F1395,Friday!F1395) -> 6.47 | AZ5: =AVERAGE(Monday!F1453,Tuesday!F1453,Wednesday!F1453,Thursday!F1453,Friday!F1453) -> 5.774 | BA5: =MEDIAN(Monday!F1453,Tuesday!F1453,Wednesday!F1453,Thursday!F1453,Friday!F1453) -> 5.7 | BB5: 2 | BC5: =AVERAGE(B5,D5,F5,H5,J5,L5,N5,P5,R5,T5,V5,X5,Z5,AB5,AD5,AF5,AH5,AJ5,AL5,AN5,AP5,AR5,AT5,AV5,AX5,AZ5) -> 5.5241538 | BD5: =MEDIAN(C5,E5,G5,I5,K5,M5,O5,Q5,S5,U5,W5,Y5,AA5,AC5,AE5,AG5,AI5,AK5,AM5,AO5,AQ5,AS5,AU5,AW5,AY5,BA5) -> 5.59
A6: 3 | B6: =AVERAGE(Monday!F4,Tuesday!F4,Wednesday!F4,Thursday!F4,Friday!F4) -> 2.656 | C6: =MEDIAN(Monday!F4,Tuesday!F4,Wednesday!F4,Thursday!F4,Friday!F4) -> 2.63 | D6: =AVERAGE(Monday!F62,Tuesday!F62,Wednesday!F62,Thursday!F62,Friday!F62) -> 2.69 | E6: =MEDIAN(Monday!F62,Tuesday!F62,Wednesday!F62,Thursday!F62,Friday!F62) -> 2.72 | F6: =AVERAGE(Monday!F120,Tuesday!F120,Wednesday!F120,Thursday!F120,Friday!F120) -> 2.764 | G6: =MEDIAN(Monday!F120,Tuesday!F120,Wednesday!F120,Thursday!F120,Friday!F120) -> 2.77 | H6: =AVERAGE(Monday!F178,Tuesday!F178,Wednesday!F178,Thursday!F178,Friday!F178) -> 2.84 | I6: =MEDIAN(Monday!F178,Tuesday!F178,Wednesday!F178,Thursday!F178,Friday!F178) -> 2.83 | J6: =AVERAGE(Monday!F236,Tuesday!F236,Wednesday!F236,Thursday!F236,Friday!F236) -> 2.976 | K6: =MEDIAN(Monday!F236,Tuesday!F236,Wednesday!F236,Thursday!F236,Friday!F236) -> 3 | L6: =AVERAGE(Monday!F294,Tuesday!F294,Wednesday!F294,Thursday!F294,Friday!F294) -> 3.062 | M6: =MEDIAN(Monday!F294,Tuesday!F294,Wednesday!F294,Thursday!F294,Friday!F294) -> 3.05 | N6: =AVERAGE(Monday!F352,Tuesday!F352,Wednesday!F352,Thursday!F352,Friday!F352) -> 3.036 | O6: =MEDIAN(Monday!F352,Tuesday!F352,Wednesday!F352,Thursday!F352,Friday!F352) -> 3.02 | P6: =AVERAGE(Monday!F410,Tuesday!F410,Wednesday!F410,Thursday!F410,Friday!F410) -> 3.038 | Q6: =MEDIAN(Monday!F410,Tuesday!F410,Wednesday!F410,Thursday!F410,Friday!F410) -> 3.07 | R6: =AVERAGE(Monday!F468,Tuesday!F468,Wednesday!F468,Thursday!F468,Friday!F468) -> 3.092 | S6: =MEDIAN(Monday!F468,Tuesday!F468,Wednesday!F468,Thursday!F468,Friday!F468) -> 3.07 | T6: =AVERAGE(Monday!F526,Tuesday!F526,Wednesday!F526,Thursday!F526,Friday!F526) -> 3.16 | U6: =MEDIAN(Monday!F526,Tuesday!F526,Wednesday!F526,Thursday!F526,Friday!F526) -> 3.12 | V6: =AVERAGE(Monday!F584,Tuesday!F584,Wednesday!F584,Thursday!F584,Friday!F584) -> 3.02 | W6: =MEDIAN(Monday!F584,Tuesday!F584,Wednesday!F584,Thursday!F584,Friday!F584) -> 3.03 | X6: =AVERAGE(Monday!F642,Tuesday!F642,Wednesday!F642,Thursday!F642,Friday!F642) -> 3.068 | Y6: =MEDIAN(Monday!F642,Tuesday!F642,Wednesday!F642,Thursday!F642,Friday!F642) -> 3.07 | Z6: =AVERAGE(Monday!F700,Tuesday!F700,Wednesday!F700,Thursday!F700,Friday!F700) -> 3.058 | AA6: =MEDIAN(Monday!F700,Tuesday!F700,Wednesday!F700,Thursday!F700,Friday!F700) -> 3.08 | AB6: =AVERAGE(Monday!F758,Tuesday!F758,Wednesday!F758,Thursday!F758,Friday!F758) -> 3.226 | AC6: =MEDIAN(Monday!F758,Tuesday!F758,Wednesday!F758,Thursday!F758,Friday!F758) -> 3.2 | AD6: =AVERAGE(Monday!F816,Tuesday!F816,Wednesday!F816,Thursday!F816,Friday!F816) -> 3.34 | AE6: =MEDIAN(Monday!F816,Tuesday!F816,Wednesday!F816,Thursday!F816,Friday!F816) -> 3.38 | AF6: =AVERAGE(Monday!F874,Tuesday!F874,Wednesday!F874,Thursday!F874,Friday!F874) -> 3.278 | AG6: =MEDIAN(Monday!F874,Tuesday!F874,Wednesday!F874,Thursday!F874,Friday!F874) -> 3.3 | AH6: =AVERAGE(Monday!F932,Tuesday!F932,Wednesday!F932,Thursday!F932,Friday!F932) -> 3.298 | AI6: =MEDIAN(Monday!F932,Tuesday!F932,Wednesday!F932,Thursday!F932,Friday!F932) -> 3.35 | AJ6: =AVERAGE(Monday!F990,Tuesday!F990,Wednesday!F990,Thursday!F990,Friday!F990) -> 3.376 | AK6: =MEDIAN(Monday!F990,Tuesday!F990,Wednesday!F990,Thursday!F990,Friday!F990) -> 3.4 | AL6: =AVERAGE(Monday!F1048,Tuesday!F1048,Wednesday!F1048,Thursday!F1048,Friday!F1048) -> 3.458 | AM6: =MEDIAN(Monday!F1048,Tuesday!F1048,Wednesday!F1048,Thursday!F1048,Friday!F1048) -> 3.42 | AN6: =AVERAGE(Monday!F1106,Tuesday!F1106,Wednesday!F1106,Thursday!F1106,Friday!F1106) -> 3.452 | AO6: =MEDIAN(Monday!F1106,Tuesday!F1106,Wednesday!F1106,Thursday!F1106,Friday!F1106) -> 3.47 | AP6: =AVERAGE(Monday!F1164,Tuesday!F1164,Wednesday!F1164,Thursday!F1164,Friday!F1164) -> 3.452 | AQ6: =MEDIAN(Monday!F1164,Tuesday!F1164,Wednesday!F1164,Thursday!F1164,Friday!F1164) -> 3.45 | AR6: =AVERAGE(Monday!F1222,Tuesday!F1222,Wednesday!F1222,Thursday!F1222,Friday!F1222) -> 3.864 | AS6: =MEDIAN(Monday!F1222,Tuesday!F1222,Wednesday!F1222,Thursday!F1222,Friday!F1222) -> 3.83 | AT6: =AVERAGE(Monday!F1280,Tuesday!F1280,Wednesday!F1280,Thursday!F1280,Friday!F1280) -> 3.976 | AU6: =MEDIAN(Monday!F1280,Tuesday!F1280,Wednesday!F1280,Thursday!F1280,Friday!F1280) -> 4 | AV6: =AVERAGE(Monday!F1338,Tuesday!F1338,Wednesday!F1338,Thursday!F1338,Friday!F1338) -> 4.012 | AW6: =MEDIAN(Monday!F1338,Tuesday!F1338,Wednesday!F1338,Thursday!F1338,Friday!F1338) -> 4.03 | AX6: =AVERAGE(Monday!F1396,Tuesday!F1396,Wednesday!F1396,Thursday!F1396,Friday!F1396) -> 4.048 | AY6: =MEDIAN(Monday!F1396,Tuesday!F1396,Wednesday!F1396,Thursday!F1396,Friday!F1396) -> 4.05 | AZ6: =AVERAGE(Monday!F1454,Tuesday!F1454,Wednesday!F1454,Thursday!F1454,Friday!F1454) -> 4.072 | BA6: =MEDIAN(Monday!F1454,Tuesday!F1454,Wednesday!F1454,Thursday!F1454,Friday!F1454) -> 3.98 | BB6: 3 | BC6: =AVERAGE(B6,D6,F6,H6,J6,L6,N6,P6,R6,T6,V6,X6,Z6,AB6,AD6,AF6,AH6,AJ6,AL6,AN6,AP6,AR6,AT6,AV6,AX6,AZ6) -> 3.2812308 | BD6: =MEDIAN(C6,E6,G6,I6,K6,M6,O6,Q6,S6,U6,W6,Y6,AA6,AC6,AE6,AG6,AI6,AK6,AM6,AO6,AQ6,AS6,AU6,AW6,AY6,BA6) -> 3.16
A7: 4 | B7: =AVERAGE(Monday!F5,Tuesday!F5,Wednesday!F5,Thursday!F5,Friday!F5) -> 2.432 | C7: =MEDIAN(Monday!F5,Tuesday!F5,Wednesday!F5,Thursday!F5,Friday!F5) -> 2.43 | D7: =AVERAGE(Monday!F63,Tuesday!F63,Wednesday!F63,Thursday!F63,Friday!F63) -> 2.532 | E7: =MEDIAN(Monday!F63,Tuesday!F63,Wednesday!F63,Thursday!F63,Friday!F63) -> 2.58 | F7: =AVERAGE(Monday!F121,Tuesday!F121,Wednesday!F121,Thursday!F121,Friday!F121) -> 2.626 | G7: =MEDIAN(Monday!F121,Tuesday!F121,Wednesday!F121,Thursday!F121,Friday!F121) -> 2.62 | H7: =AVERAGE(Monday!F179,Tuesday!F179,Wednesday!F179,Thursday!F179,Friday!F179) -> 2.586 | I7: =MEDIAN(Monday!F179,Tuesday!F179,Wednesday!F179,Thursday!F179,Friday!F179) -> 2.6 | J7: =AVERAGE(Monday!F237,Tuesday!F237,Wednesday!F237,Thursday!F237,Friday!F237) -> 2.596 | K7: =MEDIAN(Monday!F237,Tuesday!F237,Wednesday!F237,Thursday!F237,Friday!F237) -> 2.57 | L7: =AVERAGE(Monday!F295,Tuesday!F295,Wednesday!F295,Thursday!F295,Friday!F295) -> 2.606 | M7: =MEDIAN(Monday!F295,Tuesday!F295,Wednesday!F295,Thursday!F295,Friday!F295) -> 2.65 | N7: =AVERAGE(Monday!F353,Tuesday!F353,Wednesday!F353,Thursday!F353,Friday!F353) -> 2.688 | O7: =MEDIAN(Monday!F353,Tuesday!F353,Wednesday!F353,Thursday!F353,Friday!F353) -> 2.7 | P7: =AVERAGE(Monday!F411,Tuesday!F411,Wednesday!F411,Thursday!F411,Friday!F411) -> 2.746 | Q7: =MEDIAN(Monday!F411,Tuesday!F411,Wednesday!F411,Thursday!F411,Friday!F411) -> 2.73 | R7: =AVERAGE(Monday!F469,Tuesday!F469,Wednesday!F469,Thursday!F469,Friday!F469) -> 2.854 | S7: =MEDIAN(Monday!F469,Tuesday!F469,Wednesday!F469,Thursday!F469,Friday!F469) -> 2.87 | T7: =AVERAGE(Monday!F527,Tuesday!F527,Wednesday!F527,Thursday!F527,Friday!F527) -> 2.838 | U7: =MEDIAN(Monday!F527,Tuesday!F527,Wednesday!F527,Thursday!F527,Friday!F527) -> 2.83 | V7: =AVERAGE(Monday!F585,Tuesday!F585,Wednesday!F585,Thursday!F585,Friday!F585) -> 2.846 | W7: =MEDIAN(Monday!F585,Tuesday!F585,Wednesday!F585,Thursday!F585,Friday!F585) -> 2.85 | X7: =AVERAGE(Monday!F643,Tuesday!F643,Wednesday!F643,Thursday!F643,Friday!F643) -> 2.736 | Y7: =MEDIAN(Monday!F643,Tuesday!F643,Wednesday!F643,Thursday!F643,Friday!F643) -> 2.68 | Z7: =AVERAGE(Monday!F701,Tuesday!F701,Wednesday!F701,Thursday!F701,Friday!F701) -> 2.798 | AA7: =MEDIAN(Monday!F701,Tuesday!F701,Wednesday!F701,Thursday!F701,Friday!F701) -> 2.78 | AB7: =AVERAGE(Monday!F759,Tuesday!F759,Wednesday!F759,Thursday!F759,Friday!F759) -> 3.076 | AC7: =MEDIAN(Monday!F759,Tuesday!F759,Wednesday!F759,Thursday!F759,Friday!F759) -> 3.08 | AD7: =AVERAGE(Monday!F817,Tuesday!F817,Wednesday!F817,Thursday!F817,Friday!F817) -> 3.222 | AE7: =MEDIAN(Monday!F817,Tuesday!F817,Wednesday!F817,Thursday!F817,Friday!F817) -> 3.2 | AF7: =AVERAGE(Monday!F875,Tuesday!F875,Wednesday!F875,Thursday!F875,Friday!F875) -> 3.14 | AG7: =MEDIAN(Monday!F875,Tuesday!F875,Wednesday!F875,Thursday!F875,Friday!F875) -> 3.15 | AH7: =AVERAGE(Monday!F933,Tuesday!F933,Wednesday!F933,Thursday!F933,Friday!F933) -> 3.19 | AI7: =MEDIAN(Monday!F933,Tuesday!F933,Wednesday!F933,Thursday!F933,Friday!F933) -> 3.17 | AJ7: =AVERAGE(Monday!F991,Tuesday!F991,Wednesday!F991,Thursday!F991,Friday!F991) -> 3.154 | AK7: =MEDIAN(Monday!F991,Tuesday!F991,Wednesday!F991,Thursday!F991,Friday!F991) -> 3.13 | AL7: =AVERAGE(Monday!F1049,Tuesday!F1049,Wednesday!F1049,Thursday!F1049,Friday!F1049) -> 3.17 | AM7: =MEDIAN(Monday!F1049,Tuesday!F1049,Wednesday!F1049,Thursday!F1049,Friday!F1049) -> 3.08 | AN7: =AVERAGE(Monday!F1107,Tuesday!F1107,Wednesday!F1107,Thursday!F1107,Friday!F1107) -> 2.968 | AO7: =MEDIAN(Monday!F1107,Tuesday!F1107,Wednesday!F1107,Thursday!F1107,Friday!F1107) -> 2.93 | AP7: =AVERAGE(Monday!F1165,Tuesday!F1165,Wednesday!F1165,Thursday!F1165,Friday!F1165) -> 3.024 | AQ7: =MEDIAN(Monday!F1165,Tuesday!F1165,Wednesday!F1165,Thursday!F1165,Friday!F1165) -> 3 | AR7: =AVERAGE(Monday!F1223,Tuesday!F1223,Wednesday!F1223,Thursday!F1223,Friday!F1223) -> 3.294 | AS7: =MEDIAN(Monday!F1223,Tuesday!F1223,Wednesday!F1223,Thursday!F1223,Friday!F1223) -> 3.25 | AT7: =AVERAGE(Monday!F1281,Tuesday!F1281,Wednesday!F1281,Thursday!F1281,Friday!F1281) -> 3.23 | AU7: =MEDIAN(Monday!F1281,Tuesday!F1281,Wednesday!F1281,Thursday!F1281,Friday!F1281) -> 3.13 | AV7: =AVERAGE(Monday!F1339,Tuesday!F1339,Wednesday!F1339,Thursday!F1339,Friday!F1339) -> 3.41 | AW7: =MEDIAN(Monday!F1339,Tuesday!F1339,Wednesday!F1339,Thursday!F1339,Friday!F1339) -> 3.32 | AX7: =AVERAGE(Monday!F1397,Tuesday!F1397,Wednesday!F1397,Thursday!F1397,Friday!F1397) -> 3.412 | AY7: =MEDIAN(Monday!F1397,Tuesday!F1397,Wednesday!F1397,Thursday!F1397,Friday!F1397) -> 3.27 | AZ7: =AVERAGE(Monday!F1455,Tuesday!F1455,Wednesday!F1455,Thursday!F1455,Friday!F1455) -> 3.37 | BA7: =MEDIAN(Monday!F1455,Tuesday!F1455,Wednesday!F1455,Thursday!F1455,Friday!F1455) -> 3.35 | BB7: 4 | BC7: =AVERAGE(B7,D7,F7,H7,J7,L7,N7,P7,R7,T7,V7,X7,Z7,AB7,AD7,AF7,AH7,AJ7,AL7,AN7,AP7,AR7,AT7,AV7,AX7,AZ7) -> 2.944 | BD7: =MEDIAN(C7,E7,G7,I7,K7,M7,O7,Q7,S7,U7,W7,Y7,AA7,AC7,AE7,AG7,AI7,AK7,AM7,AO7,AQ7,AS7,AU7,AW7,AY7,BA7) -> 2.9
A8: 5 | B8: =AVERAGE(Monday!F6,Tuesday!F6,Wednesday!F6,Thursday!F6,Friday!F6) -> 2.666 | C8: =MEDIAN(Monday!F6,Tuesday!F6,Wednesday!F6,Thursday!F6,Friday!F6) -> 2.68 | D8: =AVERAGE(Monday!F64,Tuesday!F64,Wednesday!F64,Thursday!F64,Friday!F64) -> 2.792 | E8: =MEDIAN(Monday!F64,Tuesday!F64,Wednesday!F64,Thursday!F64,Friday!F64) -> 2.75 | F8: =AVERAGE(Monday!F122,Tuesday!F122,Wednesday!F122,Thursday!F122,Friday!F122) -> 2.864 | G8: =MEDIAN(Monday!F122,Tuesday!F122,Wednesday!F122,Thursday!F122,Friday!F122) -> 2.88 | H8: =AVERAGE(Monday!F180,Tuesday!F180,Wednesday!F180,Thursday!F180,Friday!F180) -> 2.962 | I8: =MEDIAN(Monday!F180,Tuesday!F180,Wednesday!F180,Thursday!F180,Friday!F180) -> 2.92 | J8: =AVERAGE(Monday!F238,Tuesday!F238,Wednesday!F238,Thursday!F238,Friday!F238) -> 2.97 | K8: =MEDIAN(Monday!F238,Tuesday!F238,Wednesday!F238,Thursday!F238,Friday!F238) -> 2.97 | L8: =AVERAGE(Monday!F296,Tuesday!F296,Wednesday!F296,Thursday!F296,Friday!F296) -> 3.096 | M8: =MEDIAN(Monday!F296,Tuesday!F296,Wednesday!F296,Thursday!F296,Friday!F296) -> 3.15 | N8: =AVERAGE(Monday!F354,Tuesday!F354,Wednesday!F354,Thursday!F354,Friday!F354) -> 3.158 | O8: =MEDIAN(Monday!F354,Tuesday!F354,Wednesday!F354,Thursday!F354,Friday!F354) -> 3.15 | P8: =AVERAGE(Monday!F412,Tuesday!F412,Wednesday!F412,Thursday!F412,Friday!F412) -> 3.194 | Q8: =MEDIAN(Monday!F412,Tuesday!F412,Wednesday!F412,Thursday!F412,Friday!F412) -> 3.17 | R8: =AVERAGE(Monday!F470,Tuesday!F470,Wednesday!F470,Thursday!F470,Friday!F470) -> 3.242 | S8: =MEDIAN(Monday!F470,Tuesday!F470,Wednesday!F470,Thursday!F470,Friday!F470) -> 3.2 | T8: =AVERAGE(Monday!F528,Tuesday!F528,Wednesday!F528,Thursday!F528,Friday!F528) -> 3.194 | U8: =MEDIAN(Monday!F528,Tuesday!F528,Wednesday!F528,Thursday!F528,Friday!F528) -> 3.27 | V8: =AVERAGE(Monday!F586,Tuesday!F586,Wednesday!F586,Thursday!F586,Friday!F586) -> 3.312 | W8: =MEDIAN(Monday!F586,Tuesday!F586,Wednesday!F586,Thursday!F586,Friday!F586) -> 3.33 | X8: =AVERAGE(Monday!F644,Tuesday!F644,Wednesday!F644,Thursday!F644,Friday!F644) -> 3.306 | Y8: =MEDIAN(Monday!F644,Tuesday!F644,Wednesday!F644,Thursday!F644,Friday!F644) -> 3.32 | Z8: =AVERAGE(Monday!F702,Tuesday!F702,Wednesday!F702,Thursday!F702,Friday!F702) -> 3.338 | AA8: =MEDIAN(Monday!F702,Tuesday!F702,Wednesday!F702,Thursday!F702,Friday!F702) -> 3.3 | AB8: =AVERAGE(Monday!F760,Tuesday!F760,Wednesday!F760,Thursday!F760,Friday!F760) -> 3.66 | AC8: =MEDIAN(Monday!F760,Tuesday!F760,Wednesday!F760,Thursday!F760,Friday!F760) -> 3.65 | AD8: =AVERAGE(Monday!F818,Tuesday!F818,Wednesday!F818,Thursday!F818,Friday!F818) -> 3.822 | AE8: =MEDIAN(Monday!F818,Tuesday!F818,Wednesday!F818,Thursday!F818,Friday!F818) -> 3.92 | AF8: =AVERAGE(Monday!F876,Tuesday!F876,Wednesday!F876,Thursday!F876,Friday!F876) -> 3.914 | AG8: =MEDIAN(Monday!F876,Tuesday!F876,Wednesday!F876,Thursday!F876,Friday!F876) -> 3.97 | AH8: =AVERAGE(Monday!F934,Tuesday!F934,Wednesday!F934,Thursday!F934,Friday!F934) -> 3.958 | AI8: =MEDIAN(Monday!F934,Tuesday!F934,Wednesday!F934,Thursday!F934,Friday!F934) -> 3.87 | AJ8: =AVERAGE(Monday!F992,Tuesday!F992,Wednesday!F992,Thursday!F992,Friday!F992) -> 4.028 | AK8: =MEDIAN(Monday!F992,Tuesday!F992,Wednesday!F992,Thursday!F992,Friday!F992) -> 4.22 | AL8: =AVERAGE(Monday!F1050,Tuesday!F1050,Wednesday!F1050,Thursday!F1050,Friday!F1050) -> 3.878 | AM8: =MEDIAN(Monday!F1050,Tuesday!F1050,Wednesday!F1050,Thursday!F1050,Friday!F1050) -> 3.88 | AN8: =AVERAGE(Monday!F1108,Tuesday!F1108,Wednesday!F1108,Thursday!F1108,Friday!F1108) -> 3.836 | AO8: =MEDIAN(Monday!F1108,Tuesday!F1108,Wednesday!F1108,Thursday!F1108,Friday!F1108) -> 3.73 | AP8: =AVERAGE(Monday!F1166,Tuesday!F1166,Wednesday!F1166,Thursday!F1166,Friday!F1166) -> 3.722 | AQ8: =MEDIAN(Monday!F1166,Tuesday!F1166,Wednesday!F1166,Thursday!F1166,Friday!F1166) -> 3.75 | AR8: =AVERAGE(Monday!F1224,Tuesday!F1224,Wednesday!F1224,Thursday!F1224,Friday!F1224) -> 4.542 | AS8: =MEDIAN(Monday!F1224,Tuesday!F1224,Wednesday!F1224,Thursday!F1224,Friday!F1224) -> 4.17 | AT8: =AVERAGE(Monday!F1282,Tuesday!F1282,Wednesday!F1282,Thursday!F1282,Friday!F1282) -> 5.258 | AU8: =MEDIAN(Monday!F1282,Tuesday!F1282,Wednesday!F1282,Thursday!F1282,Friday!F1282) -> 5.07 | AV8: =AVERAGE(Monday!F1340,Tuesday!F1340,Wednesday!F1340,Thursday!F1340,Friday!F1340) -> 5.434 | AW8: =MEDIAN(Monday!F1340,Tuesday!F1340,Wednesday!F1340,Thursday!F1340,Friday!F1340) -> 4.67 | AX8: =AVERAGE(Monday!F1398,Tuesday!F1398,Wednesday!F1398,Thursday!F1398,Friday!F1398) -> 4.764 | AY8: =MEDIAN(Monday!F1398,Tuesday!F1398,Wednesday!F1398,Thursday!F1398,Friday!F1398) -> 4.53 | AZ8: =AVERAGE(Monday!F1456,Tuesday!F1456,Wednesday!F1456,Thursday!F1456,Friday!F1456) -> 4.424 | BA8: =MEDIAN(Monday!F1456,Tuesday!F1456,Wednesday!F1456,Thursday!F1456,Friday!F1456) -> 4.07 | BB8: 5 | BC8: =AVERAGE(B8,D8,F8,H8,J8,L8,N8,P8,R8,T8,V8,X8,Z8,AB8,AD8,AF8,AH8,AJ8,AL8,AN8,AP8,AR8,AT8,AV8,AX8,AZ8) -> 3.6666923 | BD8: =MEDIAN(C8,E8,G8,I8,K8,M8,O8,Q8,S8,U8,W8,Y8,AA8,AC8,AE8,AG8,AI8,AK8,AM8,AO8,AQ8,AS8,AU8,AW8,AY8,BA8) -> 3.49
A9: 6 | B9: =AVERAGE(Monday!F7,Tuesday!F7,Wednesday!F7,Thursday!F7,Friday!F7) -> 2.394 | C9: =MEDIAN(Monday!F7,Tuesday!F7,Wednesday!F7,Thursday!F7,Friday!F7) -> 2.42 | D9: =AVERAGE(Monday!F65,Tuesday!F65,Wednesday!F65,Thursday!F65,Friday!F65) -> 2.436 | E9: =MEDIAN(Monday!F65,Tuesday!F65,Wednesday!F65,Thursday!F65,Friday!F65) -> 2.43 | F9: =AVERAGE(Monday!F123,Tuesday!F123,Wednesday!F123,Thursday!F123,Friday!F123) -> 2.524 | G9: =MEDIAN(Monday!F123,Tuesday!F123,Wednesday!F123,Thursday!F123,Friday!F123) -> 2.52 | H9: =AVERAGE(Monday!F181,Tuesday!F181,Wednesday!F181,Thursday!F181,Friday!F181) -> 2.564 | I9: =MEDIAN(Monday!F181,Tuesday!F181,Wednesday!F181,Thursday!F181,Friday!F181) -> 2.57 | J9: =AVERAGE(Monday!F239,Tuesday!F239,Wednesday!F239,Thursday!F239,Friday!F239) -> 2.634 | K9: =MEDIAN(Monday!F239,Tuesday!F239,Wednesday!F239,Thursday!F239,Friday!F239) -> 2.62 | L9: =AVERAGE(Monday!F297,Tuesday!F297,Wednesday!F297,Thursday!F297,Friday!F297) -> 2.68 | M9: =MEDIAN(Monday!F297,Tuesday!F297,Wednesday!F297,Thursday!F297,Friday!F297) -> 2.67 | N9: =AVERAGE(Monday!F355,Tuesday!F355,Wednesday!F355,Thursday!F355,Friday!F355) -> 2.768 | O9: =MEDIAN(Monday!F355,Tuesday!F355,Wednesday!F355,Thursday!F355,Friday!F355) -> 2.77 | P9: =AVERAGE(Monday!F413,Tuesday!F413,Wednesday!F413,Thursday!F413,Friday!F413) -> 2.716 | Q9: =MEDIAN(Monday!F413,Tuesday!F413,Wednesday!F413,Thursday!F413,Friday!F413) -> 2.73 | R9: =AVERAGE(Monday!F471,Tuesday!F471,Wednesday!F471,Thursday!F471,Friday!F471) -> 2.686 | S9: =MEDIAN(Monday!F471,Tuesday!F471,Wednesday!F471,Thursday!F471,Friday!F471) -> 2.68 | T9: =AVERAGE(Monday!F529,Tuesday!F529,Wednesday!F529,Thursday!F529,Friday!F529) -> 2.634 | U9: =MEDIAN(Monday!F529,Tuesday!F529,Wednesday!F529,Thursday!F529,Friday!F529) -> 2.65 | V9: =AVERAGE(Monday!F587,Tuesday!F587,Wednesday!F587,Thursday!F587,Friday!F587) -> 2.746 | W9: =MEDIAN(Monday!F587,Tuesday!F587,Wednesday!F587,Thursday!F587,Friday!F587) -> 2.75 | X9: =AVERAGE(Monday!F645,Tuesday!F645,Wednesday!F645,Thursday!F645,Friday!F645) -> 2.706 | Y9: =MEDIAN(Monday!F645,Tuesday!F645,Wednesday!F645,Thursday!F645,Friday!F645) -> 2.67 | Z9: =AVERAGE(Monday!F703,Tuesday!F703,Wednesday!F703,Thursday!F703,Friday!F703) -> 2.71 | AA9: =MEDIAN(Monday!F703,Tuesday!F703,Wednesday!F703,Thursday!F703,Friday!F703) -> 2.72 | AB9: =AVERAGE(Monday!F761,Tuesday!F761,Wednesday!F761,Thursday!F761,Friday!F761) -> 2.736 | AC9: =MEDIAN(Monday!F761,Tuesday!F761,Wednesday!F761,Thursday!F761,Friday!F761) -> 2.73 | AD9: =AVERAGE(Monday!F819,Tuesday!F819,Wednesday!F819,Thursday!F819,Friday!F819) -> 2.778 | AE9: =MEDIAN(Monday!F819,Tuesday!F819,Wednesday!F819,Thursday!F819,Friday!F819) -> 2.78 | AF9: =AVERAGE(Monday!F877,Tuesday!F877,Wednesday!F877,Thursday!F877,Friday!F877) -> 2.85 | AG9: =MEDIAN(Monday!F877,Tuesday!F877,Wednesday!F877,Thursday!F877,Friday!F877) -> 2.83 | AH9: =AVERAGE(Monday!F935,Tuesday!F935,Wednesday!F935,Thursday!F935,Friday!F935) -> 2.946 | AI9: =MEDIAN(Monday!F935,Tuesday!F935,Wednesday!F935,Thursday!F935,Friday!F935) -> 2.85 | AJ9: =AVERAGE(Monday!F993,Tuesday!F993,Wednesday!F993,Thursday!F993,Friday!F993) -> 2.86 | AK9: =MEDIAN(Monday!F993,Tuesday!F993,Wednesday!F993,Thursday!F993,Friday!F993) -> 2.82 | AL9: =AVERAGE(Monday!F1051,Tuesday!F1051,Wednesday!F1051,Thursday!F1051,Friday!F1051) -> 2.876 | AM9: =MEDIAN(Monday!F1051,Tuesday!F1051,Wednesday!F1051,Thursday!F1051,Friday!F1051) -> 2.78 | AN9: =AVERAGE(Monday!F1109,Tuesday!F1109,Wednesday!F1109,Thursday!F1109,Friday!F1109) -> 2.85 | AO9: =MEDIAN(Monday!F1109,Tuesday!F1109,Wednesday!F1109,Thursday!F1109,Friday!F1109) -> 2.85 | AP9: =AVERAGE(Monday!F1167,Tuesday!F1167,Wednesday!F1167,Thursday!F1167,Friday!F1167) -> 2.738 | AQ9: =MEDIAN(Monday!F1167,Tuesday!F1167,Wednesday!F1167,Thursday!F1167,Friday!F1167) -> 2.73 | AR9: =AVERAGE(Monday!F1225,Tuesday!F1225,Wednesday!F1225,Thursday!F1225,Friday!F1225) -> 2.75 | AS9: =MEDIAN(Monday!F1225,Tuesday!F1225,Wednesday!F1225,Thursday!F1225,Friday!F1225) -> 2.8 | AT9: =AVERAGE(Monday!F1283,Tuesday!F1283,Wednesday!F1283,Thursday!F1283,Friday!F1283) -> 2.824 | AU9: =MEDIAN(Monday!F1283,Tuesday!F1283,Wednesday!F1283,Thursday!F1283,Friday!F1283) -> 2.82 | AV9: =AVERAGE(Monday!F1341,Tuesday!F1341,Wednesday!F1341,Thursday!F1341,Friday!F1341) -> 2.726 | AW9: =MEDIAN(Monday!F1341,Tuesday!F1341,Wednesday!F1341,Thursday!F1341,Friday!F1341) -> 2.72 | AX9: =AVERAGE(Monday!F1399,Tuesday!F1399,Wednesday!F1399,Thursday!F1399,Friday!F1399) -> 2.726 | AY9: =MEDIAN(Monday!F1399,Tuesday!F1399,Wednesday!F1399,Thursday!F1399,Friday!F1399) -> 2.72 | AZ9: =AVERAGE(Monday!F1457,Tuesday!F1457,Wednesday!F1457,Thursday!F1457,Friday!F1457) -> 2.77 | BA9: =MEDIAN(Monday!F1457,Tuesday!F1457,Wednesday!F1457,Thursday!F1457,Friday!F1457) -> 2.8 | BB9: 6 | BC9: =AVERAGE(B9,D9,F9,H9,J9,L9,N9,P9,R9,T9,V9,X9,Z9,AB9,AD9,AF9,AH9,AJ9,AL9,AN9,AP9,AR9,AT9,AV9,AX9,AZ9) -> 2.7164615 | BD9: =MEDIAN(C9,E9,G9,I9,K9,M9,O9,Q9,S9,U9,W9,Y9,AA9,AC9,AE9,AG9,AI9,AK9,AM9,AO9,AQ9,AS9,AU9,AW9,AY9,BA9) -> 2.73
A10: 7 | B10: =AVERAGE(Monday!F8,Tuesday!F8,Wednesday!F8,Thursday!F8,Friday!F8) -> 2.45 | C10: =MEDIAN(Monday!F8,Tuesday!F8,Wednesday!F8,Thursday!F8,Friday!F8) -> 2.45 | D10: =AVERAGE(Monday!F66,Tuesday!F66,Wednesday!F66,Thursday!F66,Friday!F66) -> 2.51 | E10: =MEDIAN(Monday!F66,Tuesday!F66,Wednesday!F66,Thursday!F66,Friday!F66) -> 2.52 | F10: =AVERAGE(Monday!F124,Tuesday!F124,Wednesday!F124,Thursday!F124,Friday!F124) -> 2.562 | G10: =MEDIAN(Monday!F124,Tuesday!F124,Wednesday!F124,Thursday!F124,Friday!F124) -> 2.57 | H10: =AVERAGE(Monday!F182,Tuesday!F182,Wednesday!F182,Thursday!F182,Friday!F182) -> 2.552 | I10: =MEDIAN(Monday!F182,Tuesday!F182,Wednesday!F182,Thursday!F182,Friday!F182) -> 2.55 | J10: =AVERAGE(Monday!F240,Tuesday!F240,Wednesday!F240,Thursday!F240,Friday!F240) -> 2.66 | K10: =MEDIAN(Monday!F240,Tuesday!F240,Wednesday!F240,Thursday!F240,Friday!F240) -> 2.68 | L10: =AVERAGE(Monday!F298,Tuesday!F298,Wednesday!F298,Thursday!F298,Friday!F298) -> 2.716 | M10: =MEDIAN(Monday!F298,Tuesday!F298,Wednesday!F298,Thursday!F298,Friday!F298) -> 2.7 | N10: =AVERAGE(Monday!F356,Tuesday!F356,Wednesday!F356,Thursday!F356,Friday!F356) -> 2.732 | O10: =MEDIAN(Monday!F356,Tuesday!F356,Wednesday!F356,Thursday!F356,Friday!F356) -> 2.73 | P10: =AVERAGE(Monday!F414,Tuesday!F414,Wednesday!F414,Thursday!F414,Friday!F414) -> 2.688 | Q10: =MEDIAN(Monday!F414,Tuesday!F414,Wednesday!F414,Thursday!F414,Friday!F414) -> 2.73 | R10: =AVERAGE(Monday!F472,Tuesday!F472,Wednesday!F472,Thursday!F472,Friday!F472) -> 2.644 | S10: =MEDIAN(Monday!F472,Tuesday!F472,Wednesday!F472,Thursday!F472,Friday!F472) -> 2.67 | T10: =AVERAGE(Monday!F530,Tuesday!F530,Wednesday!F530,Thursday!F530,Friday!F530) -> 2.606 | U10: =MEDIAN(Monday!F530,Tuesday!F530,Wednesday!F530,Thursday!F530,Friday!F530) -> 2.63 | V10: =AVERAGE(Monday!F588,Tuesday!F588,Wednesday!F588,Thursday!F588,Friday!F588) -> 2.712 | W10: =MEDIAN(Monday!F588,Tuesday!F588,Wednesday!F588,Thursday!F588,Friday!F588) -> 2.67 | X10: =AVERAGE(Monday!F646,Tuesday!F646,Wednesday!F646,Thursday!F646,Friday!F646) -> 2.664 | Y10: =MEDIAN(Monday!F646,Tuesday!F646,Wednesday!F646,Thursday!F646,Friday!F646) -> 2.63 | Z10: =AVERAGE(Monday!F704,Tuesday!F704,Wednesday!F704,Thursday!F704,Friday!F704) -> 2.694 | AA10: =MEDIAN(Monday!F704,Tuesday!F704,Wednesday!F704,Thursday!F704,Friday!F704) -> 2.68 | AB10: =AVERAGE(Monday!F762,Tuesday!F762,Wednesday!F762,Thursday!F762,Friday!F762) -> 2.65 | AC10: =MEDIAN(Monday!F762,Tuesday!F762,Wednesday!F762,Thursday!F762,Friday!F762) -> 2.68 | AD10: =AVERAGE(Monday!F820,Tuesday!F820,Wednesday!F820,Thursday!F820,Friday!F820) -> 2.73 | AE10: =MEDIAN(Monday!F820,Tuesday!F820,Wednesday!F820,Thursday!F820,Friday!F820) -> 2.75 | AF10: =AVERAGE(Monday!F878,Tuesday!F878,Wednesday!F878,Thursday!F878,Friday!F878) -> 2.756 | AG10: =MEDIAN(Monday!F878,Tuesday!F878,Wednesday!F878,Thursday!F878,Friday!F878) -> 2.73 | AH10: =AVERAGE(Monday!F936,Tuesday!F936,Wednesday!F936,Thursday!F936,Friday!F936) -> 2.698 | AI10: =MEDIAN(Monday!F936,Tuesday!F936,Wednesday!F936,Thursday!F936,Friday!F936) -> 2.73 | AJ10: =AVERAGE(Monday!F994,Tuesday!F994,Wednesday!F994,Thursday!F994,Friday!F994) -> 2.846 | AK10: =MEDIAN(Monday!F994,Tuesday!F994,Wednesday!F994,Thursday!F994,Friday!F994) -> 2.85 | AL10: =AVERAGE(Monday!F1052,Tuesday!F1052,Wednesday!F1052,Thursday!F1052,Friday!F1052) -> 2.772 | AM10: =MEDIAN(Monday!F1052,Tuesday!F1052,Wednesday!F1052,Thursday!F1052,Friday!F1052) -> 2.75 | AN10: =AVERAGE(Monday!F1110,Tuesday!F1110,Wednesday!F1110,Thursday!F1110,Friday!F1110) -> 2.712 | AO10: =MEDIAN(Monday!F1110,Tuesday!F1110,Wednesday!F1110,Thursday!F1110,Friday!F1110) -> 2.73 | AP10: =AVERAGE(Monday!F1168,Tuesday!F1168,Wednesday!F1168,Thursday!F1168,Friday!F1168) -> 2.732 | AQ10: =MEDIAN(Monday!F1168,Tuesday!F1168,Wednesday!F1168,Thursday!F1168,Friday!F1168) -> 2.8 | AR10: =AVERAGE(Monday!F1226,Tuesday!F1226,Wednesday!F1226,Thursday!F1226,Friday!F1226) -> 2.772 | AS10: =MEDIAN(Monday!F1226,Tuesday!F1226,Wednesday!F1226,Thursday!F1226,Friday!F1226) -> 2.75 | AT10: =AVERAGE(Monday!F1284,Tuesday!F1284,Wednesday!F1284,Thursday!F1284,Friday!F1284) -> 2.726 | AU10: =MEDIAN(Monday!F1284,Tuesday!F1284,Wednesday!F1284,Thursday!F1284,Friday!F1284) -> 2.7 | AV10: =AVERAGE(Monday!F1342,Tuesday!F1342,Wednesday!F1342,Thursday!F1342,Friday!F1342) -> 2.738 | AW10: =MEDIAN(Monday!F1342,Tuesday!F1342,Wednesday!F1342,Thursday!F1342,Friday!F1342) -> 2.77 | AX10: =AVERAGE(Monday!F1400,Tuesday!F1400,Wednesday!F1400,Thursday!F1400,Friday!F1400) -> 2.686 | AY10: =MEDIAN(Monday!F1400,Tuesday!F1400,Wednesday!F1400,Thursday!F1400,Friday!F1400) -> 2.67 | AZ10: =AVERAGE(Monday!F1458,Tuesday!F1458,Wednesday!F1458,Thursday!F1458,Friday!F1458) -> 2.716 | BA10: =MEDIAN(Monday!F1458,Tuesday!F1458,Wednesday!F1458,Thursday!F1458,Friday!F1458) -> 2.7 | BB10: 7 | BC10: =AVERAGE(B10,D10,F10,H10,J10,L10,N10,P10,R10,T10,V10,X10,Z10,AB10,AD10,AF10,AH10,AJ10,AL10,AN10,AP10,AR10,AT10,AV10,AX10,AZ10) -> 2.6816923 | BD10: =MEDIAN(C10,E10,G10,I10,K10,M10,O10,Q10,S10,U10,W10,Y10,AA10,AC10,AE10,AG10,AI10,AK10,AM10,AO10,AQ10,AS10,AU10,AW10,AY10,BA10) -> 2.7
A11: 8 | B11: =AVERAGE(Monday!F9,Tuesday!F9,Wednesday!F9,Thursday!F9,Friday!F9) -> 2.73 | C11: =MEDIAN(Monday!F9,Tuesday!F9,Wednesday!F9,Thursday!F9,Friday!F9) -> 2.73 | D11: =AVERAGE(Monday!F67,Tuesday!F67,Wednesday!F67,Thursday!F67,Friday!F67) -> 2.854 | E11: =MEDIAN(Monday!F67,Tuesday!F67,Wednesday!F67,Thursday!F67,Friday!F67) -> 2.85 | F11: =AVERAGE(Monday!F125,Tuesday!F125,Wednesday!F125,Thursday!F125,Friday!F125) -> 3.036 | G11: =MEDIAN(Monday!F125,Tuesday!F125,Wednesday!F125,Thursday!F125,Friday!F125) -> 3.05 | H11: =AVERAGE(Monday!F183,Tuesday!F183,Wednesday!F183,Thursday!F183,Friday!F183) -> 3.032 | I11: =MEDIAN(Monday!F183,Tuesday!F183,Wednesday!F183,Thursday!F183,Friday!F183) -> 3.08 | J11: =AVERAGE(Monday!F241,Tuesday!F241,Wednesday!F241,Thursday!F241,Friday!F241) -> 3.342 | K11: =MEDIAN(Monday!F241,Tuesday!F241,Wednesday!F241,Thursday!F241,Friday!F241) -> 3.33 | L11: =AVERAGE(Monday!F299,Tuesday!F299,Wednesday!F299,Thursday!F299,Friday!F299) -> 3.6 | M11: =MEDIAN(Monday!F299,Tuesday!F299,Wednesday!F299,Thursday!F299,Friday!F299) -> 3.57 | N11: =AVERAGE(Monday!F357,Tuesday!F357,Wednesday!F357,Thursday!F357,Friday!F357) -> 3.524 | O11: =MEDIAN(Monday!F357,Tuesday!F357,Wednesday!F357,Thursday!F357,Friday!F357) -> 3.52 | P11: =AVERAGE(Monday!F415,Tuesday!F415,Wednesday!F415,Thursday!F415,Friday!F415) -> 3.494 | Q11: =MEDIAN(Monday!F415,Tuesday!F415,Wednesday!F415,Thursday!F415,Friday!F415) -> 3.5 | R11: =AVERAGE(Monday!F473,Tuesday!F473,Wednesday!F473,Thursday!F473,Friday!F473) -> 3.304 | S11: =MEDIAN(Monday!F473,Tuesday!F473,Wednesday!F473,Thursday!F473,Friday!F473) -> 3.32 | T11: =AVERAGE(Monday!F531,Tuesday!F531,Wednesday!F531,Thursday!F531,Friday!F531) -> 3.256 | U11: =MEDIAN(Monday!F531,Tuesday!F531,Wednesday!F531,Thursday!F531,Friday!F531) -> 3.28 | V11: =AVERAGE(Monday!F589,Tuesday!F589,Wednesday!F589,Thursday!F589,Friday!F589) -> 3.37 | W11: =MEDIAN(Monday!F589,Tuesday!F589,Wednesday!F589,Thursday!F589,Friday!F589) -> 3.33 | X11: =AVERAGE(Monday!F647,Tuesday!F647,Wednesday!F647,Thursday!F647,Friday!F647) -> 3.268 | Y11: =MEDIAN(Monday!F647,Tuesday!F647,Wednesday!F647,Thursday!F647,Friday!F647) -> 3.23 | Z11: =AVERAGE(Monday!F705,Tuesday!F705,Wednesday!F705,Thursday!F705,Friday!F705) -> 3.332 | AA11: =MEDIAN(Monday!F705,Tuesday!F705,Wednesday!F705,Thursday!F705,Friday!F705) -> 3.35 | AB11: =AVERAGE(Monday!F763,Tuesday!F763,Wednesday!F763,Thursday!F763,Friday!F763) -> 3.254 | AC11: =MEDIAN(Monday!F763,Tuesday!F763,Wednesday!F763,Thursday!F763,Friday!F763) -> 3.25 | AD11: =AVERAGE(Monday!F821,Tuesday!F821,Wednesday!F821,Thursday!F821,Friday!F821) -> 3.44 | AE11: =MEDIAN(Monday!F821,Tuesday!F821,Wednesday!F821,Thursday!F821,Friday!F821) -> 3.45 | AF11: =AVERAGE(Monday!F879,Tuesday!F879,Wednesday!F879,Thursday!F879,Friday!F879) -> 3.442 | AG11: =MEDIAN(Monday!F879,Tuesday!F879,Wednesday!F879,Thursday!F879,Friday!F879) -> 3.43 | AH11: =AVERAGE(Monday!F937,Tuesday!F937,Wednesday!F937,Thursday!F937,Friday!F937) -> 3.354 | AI11: =MEDIAN(Monday!F937,Tuesday!F937,Wednesday!F937,Thursday!F937,Friday!F937) -> 3.35 | AJ11: =AVERAGE(Monday!F995,Tuesday!F995,Wednesday!F995,Thursday!F995,Friday!F995) -> 3.394 | AK11: =MEDIAN(Monday!F995,Tuesday!F995,Wednesday!F995,Thursday!F995,Friday!F995) -> 3.38 | AL11: =AVERAGE(Monday!F1053,Tuesday!F1053,Wednesday!F1053,Thursday!F1053,Friday!F1053) -> 3.352 | AM11: =MEDIAN(Monday!F1053,Tuesday!F1053,Wednesday!F1053,Thursday!F1053,Friday!F1053) -> 3.35 | AN11: =AVERAGE(Monday!F1111,Tuesday!F1111,Wednesday!F1111,Thursday!F1111,Friday!F1111) -> 3.226 | AO11: =MEDIAN(Monday!F1111,Tuesday!F1111,Wednesday!F1111,Thursday!F1111,Friday!F1111) -> 3.28 | AP11: =AVERAGE(Monday!F1169,Tuesday!F1169,Wednesday!F1169,Thursday!F1169,Friday!F1169) -> 3.424 | AQ11: =MEDIAN(Monday!F1169,Tuesday!F1169,Wednesday!F1169,Thursday!F1169,Friday!F1169) -> 3.43 | AR11: =AVERAGE(Monday!F1227,Tuesday!F1227,Wednesday!F1227,Thursday!F1227,Friday!F1227) -> 3.302 | AS11: =MEDIAN(Monday!F1227,Tuesday!F1227,Wednesday!F1227,Thursday!F1227,Friday!F1227) -> 3.33 | AT11: =AVERAGE(Monday!F1285,Tuesday!F1285,Wednesday!F1285,Thursday!F1285,Friday!F1285) -> 3.344 | AU11: =MEDIAN(Monday!F1285,Tuesday!F1285,Wednesday!F1285,Thursday!F1285,Friday!F1285) -> 3.4 | AV11: =AVERAGE(Monday!F1343,Tuesday!F1343,Wednesday!F1343,Thursday!F1343,Friday!F1343) -> 3.24 | AW11: =MEDIAN(Monday!F1343,Tuesday!F1343,Wednesday!F1343,Thursday!F1343,Friday!F1343) -> 3.25 | AX11: =AVERAGE(Monday!F1401,Tuesday!F1401,Wednesday!F1401,Thursday!F1401,Friday!F1401) -> 3.234 | AY11: =MEDIAN(Monday!F1401,Tuesday!F1401,Wednesday!F1401,Thursday!F1401,Friday!F1401) -> 3.18 | AZ11: =AVERAGE(Monday!F1459,Tuesday!F1459,Wednesday!F1459,Thursday!F1459,Friday!F1459) -> 3.236 | BA11: =MEDIAN(Monday!F1459,Tuesday!F1459,Wednesday!F1459,Thursday!F1459,Friday!F1459) -> 3.23 | BB11: 8 | BC11: =AVERAGE(B11,D11,F11,H11,J11,L11,N11,P11,R11,T11,V11,X11,Z11,AB11,AD11,AF11,AH11,AJ11,AL11,AN11,AP11,AR11,AT11,AV11,AX11,AZ11) -> 3.284 | BD11: =MEDIAN(C11,E11,G11,I11,K11,M11,O11,Q11,S11,U11,W11,Y11,AA11,AC11,AE11,AG11,AI11,AK11,AM11,AO11,AQ11,AS11,AU11,AW11,AY11,BA11) -> 3.33
